2025-04-21 21:00:21,387 - bot - ERROR - Ошибка при логировании состояния: Object of type MagicMock is not JSON serializable
2025-04-21 21:00:21,387 - bot - ERROR - Ошибка при логировании состояния: Object of type MagicMock is not JSON serializable
2025-04-21 21:01:13,917 - bot - ERROR - Ошибка при логировании состояния: Object of type MagicMock is not JSON serializable
2025-04-21 21:01:13,917 - bot - ERROR - Ошибка при логировании состояния: Object of type MagicMock is not JSON serializable
2025-04-21 21:02:11,805 - bot - ERROR - Ошибка при логировании состояния: Object of type MagicMock is not JSON serializable
2025-04-21 21:02:11,805 - bot - ERROR - Ошибка при логировании состояния: Object of type MagicMock is not JSON serializable
2025-04-21 21:07:33,280 - bot - ERROR - Ошибка при логировании состояния: Object of type MagicMock is not JSON serializable
2025-04-21 21:07:33,280 - bot - ERROR - Ошибка при логировании состояния: Object of type MagicMock is not JSON serializable
2025-04-21 21:07:45,668 - bot - ERROR - Ошибка при логировании состояния: Object of type MagicMock is not JSON serializable
2025-04-21 21:07:45,668 - bot - ERROR - Ошибка при логировании состояния: Object of type MagicMock is not JSON serializable
2025-04-22 13:03:56,402 - telegram.ext.Updater - ERROR - Error while getting Updates: httpx.ConnectError: [Errno 8] nodename nor servname provided, or not known
2025-04-22 13:03:56,402 - telegram.ext.Updater - ERROR - Error while getting Updates: httpx.ConnectError: [Errno 8] nodename nor servname provided, or not known
2025-04-22 13:03:56,450 - __main__ - ERROR - Update None вызвал ошибку httpx.ConnectError: [Errno 8] nodename nor servname provided, or not known
Traceback (most recent call last):
  File "/Library/Frameworks/Python.framework/Versions/3.13/lib/python3.13/site-packages/httpx/_transports/default.py", line 101, in map_httpcore_exceptions
    yield
  File "/Library/Frameworks/Python.framework/Versions/3.13/lib/python3.13/site-packages/httpx/_transports/default.py", line 394, in handle_async_request
    resp = await self._pool.handle_async_request(req)
           ^^^^^^^^^^^^^^^^^^^^^^^^^^^^^^^^^^^^^^^^^^
  File "/Library/Frameworks/Python.framework/Versions/3.13/lib/python3.13/site-packages/httpcore/_async/connection_pool.py", line 256, in handle_async_request
    raise exc from None
  File "/Library/Frameworks/Python.framework/Versions/3.13/lib/python3.13/site-packages/httpcore/_async/connection_pool.py", line 236, in handle_async_request
    response = await connection.handle_async_request(
               ^^^^^^^^^^^^^^^^^^^^^^^^^^^^^^^^^^^^^^
        pool_request.request
        ^^^^^^^^^^^^^^^^^^^^
    )
    ^
  File "/Library/Frameworks/Python.framework/Versions/3.13/lib/python3.13/site-packages/httpcore/_async/connection.py", line 101, in handle_async_request
    raise exc
  File "/Library/Frameworks/Python.framework/Versions/3.13/lib/python3.13/site-packages/httpcore/_async/connection.py", line 78, in handle_async_request
    stream = await self._connect(request)
             ^^^^^^^^^^^^^^^^^^^^^^^^^^^^
  File "/Library/Frameworks/Python.framework/Versions/3.13/lib/python3.13/site-packages/httpcore/_async/connection.py", line 124, in _connect
    stream = await self._network_backend.connect_tcp(**kwargs)
             ^^^^^^^^^^^^^^^^^^^^^^^^^^^^^^^^^^^^^^^^^^^^^^^^^
  File "/Library/Frameworks/Python.framework/Versions/3.13/lib/python3.13/site-packages/httpcore/_backends/auto.py", line 31, in connect_tcp
    return await self._backend.connect_tcp(
           ^^^^^^^^^^^^^^^^^^^^^^^^^^^^^^^^
    ...<5 lines>...
    )
    ^
  File "/Library/Frameworks/Python.framework/Versions/3.13/lib/python3.13/site-packages/httpcore/_backends/anyio.py", line 113, in connect_tcp
    with map_exceptions(exc_map):
         ~~~~~~~~~~~~~~^^^^^^^^^
  File "/Library/Frameworks/Python.framework/Versions/3.13/lib/python3.13/contextlib.py", line 162, in __exit__
    self.gen.throw(value)
    ~~~~~~~~~~~~~~^^^^^^^
  File "/Library/Frameworks/Python.framework/Versions/3.13/lib/python3.13/site-packages/httpcore/_exceptions.py", line 14, in map_exceptions
    raise to_exc(exc) from exc
httpcore.ConnectError: [Errno 8] nodename nor servname provided, or not known

The above exception was the direct cause of the following exception:

Traceback (most recent call last):
  File "/Library/Frameworks/Python.framework/Versions/3.13/lib/python3.13/site-packages/telegram/request/_httpxrequest.py", line 276, in do_request
    res = await self._client.request(
          ^^^^^^^^^^^^^^^^^^^^^^^^^^^
    ...<6 lines>...
    )
    ^
  File "/Library/Frameworks/Python.framework/Versions/3.13/lib/python3.13/site-packages/httpx/_client.py", line 1540, in request
    return await self.send(request, auth=auth, follow_redirects=follow_redirects)
           ^^^^^^^^^^^^^^^^^^^^^^^^^^^^^^^^^^^^^^^^^^^^^^^^^^^^^^^^^^^^^^^^^^^^^^
  File "/Library/Frameworks/Python.framework/Versions/3.13/lib/python3.13/site-packages/httpx/_client.py", line 1629, in send
    response = await self._send_handling_auth(
               ^^^^^^^^^^^^^^^^^^^^^^^^^^^^^^^
    ...<4 lines>...
    )
    ^
  File "/Library/Frameworks/Python.framework/Versions/3.13/lib/python3.13/site-packages/httpx/_client.py", line 1657, in _send_handling_auth
    response = await self._send_handling_redirects(
               ^^^^^^^^^^^^^^^^^^^^^^^^^^^^^^^^^^^^
    ...<3 lines>...
    )
    ^
  File "/Library/Frameworks/Python.framework/Versions/3.13/lib/python3.13/site-packages/httpx/_client.py", line 1694, in _send_handling_redirects
    response = await self._send_single_request(request)
               ^^^^^^^^^^^^^^^^^^^^^^^^^^^^^^^^^^^^^^^^
  File "/Library/Frameworks/Python.framework/Versions/3.13/lib/python3.13/site-packages/httpx/_client.py", line 1730, in _send_single_request
    response = await transport.handle_async_request(request)
               ^^^^^^^^^^^^^^^^^^^^^^^^^^^^^^^^^^^^^^^^^^^^^
  File "/Library/Frameworks/Python.framework/Versions/3.13/lib/python3.13/site-packages/httpx/_transports/default.py", line 393, in handle_async_request
    with map_httpcore_exceptions():
         ~~~~~~~~~~~~~~~~~~~~~~~^^
  File "/Library/Frameworks/Python.framework/Versions/3.13/lib/python3.13/contextlib.py", line 162, in __exit__
    self.gen.throw(value)
    ~~~~~~~~~~~~~~^^^^^^^
  File "/Library/Frameworks/Python.framework/Versions/3.13/lib/python3.13/site-packages/httpx/_transports/default.py", line 118, in map_httpcore_exceptions
    raise mapped_exc(message) from exc
httpx.ConnectError: [Errno 8] nodename nor servname provided, or not known

The above exception was the direct cause of the following exception:

Traceback (most recent call last):
  File "/Library/Frameworks/Python.framework/Versions/3.13/lib/python3.13/site-packages/telegram/ext/_updater.py", line 755, in _network_loop_retry
    if not await do_action():
           ^^^^^^^^^^^^^^^^^
  File "/Library/Frameworks/Python.framework/Versions/3.13/lib/python3.13/site-packages/telegram/ext/_updater.py", line 749, in do_action
    return action_cb_task.result()
           ~~~~~~~~~~~~~~~~~~~~~^^
  File "/Library/Frameworks/Python.framework/Versions/3.13/lib/python3.13/site-packages/telegram/ext/_updater.py", line 389, in polling_action_cb
    raise exc
  File "/Library/Frameworks/Python.framework/Versions/3.13/lib/python3.13/site-packages/telegram/ext/_updater.py", line 378, in polling_action_cb
    updates = await self.bot.get_updates(
              ^^^^^^^^^^^^^^^^^^^^^^^^^^^
    ...<7 lines>...
    )
    ^
  File "/Library/Frameworks/Python.framework/Versions/3.13/lib/python3.13/site-packages/telegram/ext/_extbot.py", line 649, in get_updates
    updates = await super().get_updates(
              ^^^^^^^^^^^^^^^^^^^^^^^^^^
    ...<9 lines>...
    )
    ^
  File "/Library/Frameworks/Python.framework/Versions/3.13/lib/python3.13/site-packages/telegram/_bot.py", line 4364, in get_updates
    await self._post(
    ^^^^^^^^^^^^^^^^^
    ...<7 lines>...
    ),
    ^
  File "/Library/Frameworks/Python.framework/Versions/3.13/lib/python3.13/site-packages/telegram/_bot.py", line 622, in _post
    return await self._do_post(
           ^^^^^^^^^^^^^^^^^^^^
    ...<6 lines>...
    )
    ^
  File "/Library/Frameworks/Python.framework/Versions/3.13/lib/python3.13/site-packages/telegram/ext/_extbot.py", line 355, in _do_post
    return await super()._do_post(
           ^^^^^^^^^^^^^^^^^^^^^^^
    ...<6 lines>...
    )
    ^
  File "/Library/Frameworks/Python.framework/Versions/3.13/lib/python3.13/site-packages/telegram/_bot.py", line 651, in _do_post
    result = await request.post(
             ^^^^^^^^^^^^^^^^^^^
    ...<6 lines>...
    )
    ^
  File "/Library/Frameworks/Python.framework/Versions/3.13/lib/python3.13/site-packages/telegram/request/_baserequest.py", line 200, in post
    result = await self._request_wrapper(
             ^^^^^^^^^^^^^^^^^^^^^^^^^^^^
    ...<7 lines>...
    )
    ^
  File "/Library/Frameworks/Python.framework/Versions/3.13/lib/python3.13/site-packages/telegram/request/_baserequest.py", line 342, in _request_wrapper
    raise exc
  File "/Library/Frameworks/Python.framework/Versions/3.13/lib/python3.13/site-packages/telegram/request/_baserequest.py", line 332, in _request_wrapper
    code, payload = await self.do_request(
                    ^^^^^^^^^^^^^^^^^^^^^^
    ...<7 lines>...
    )
    ^
  File "/Library/Frameworks/Python.framework/Versions/3.13/lib/python3.13/site-packages/telegram/request/_httpxrequest.py", line 300, in do_request
    raise NetworkError(f"httpx.{err.__class__.__name__}: {err}") from err
telegram.error.NetworkError: httpx.ConnectError: [Errno 8] nodename nor servname provided, or not known
2025-04-22 13:03:56,450 - __main__ - ERROR - Update None вызвал ошибку httpx.ConnectError: [Errno 8] nodename nor servname provided, or not known
Traceback (most recent call last):
  File "/Library/Frameworks/Python.framework/Versions/3.13/lib/python3.13/site-packages/httpx/_transports/default.py", line 101, in map_httpcore_exceptions
    yield
  File "/Library/Frameworks/Python.framework/Versions/3.13/lib/python3.13/site-packages/httpx/_transports/default.py", line 394, in handle_async_request
    resp = await self._pool.handle_async_request(req)
           ^^^^^^^^^^^^^^^^^^^^^^^^^^^^^^^^^^^^^^^^^^
  File "/Library/Frameworks/Python.framework/Versions/3.13/lib/python3.13/site-packages/httpcore/_async/connection_pool.py", line 256, in handle_async_request
    raise exc from None
  File "/Library/Frameworks/Python.framework/Versions/3.13/lib/python3.13/site-packages/httpcore/_async/connection_pool.py", line 236, in handle_async_request
    response = await connection.handle_async_request(
               ^^^^^^^^^^^^^^^^^^^^^^^^^^^^^^^^^^^^^^
        pool_request.request
        ^^^^^^^^^^^^^^^^^^^^
    )
    ^
  File "/Library/Frameworks/Python.framework/Versions/3.13/lib/python3.13/site-packages/httpcore/_async/connection.py", line 101, in handle_async_request
    raise exc
  File "/Library/Frameworks/Python.framework/Versions/3.13/lib/python3.13/site-packages/httpcore/_async/connection.py", line 78, in handle_async_request
    stream = await self._connect(request)
             ^^^^^^^^^^^^^^^^^^^^^^^^^^^^
  File "/Library/Frameworks/Python.framework/Versions/3.13/lib/python3.13/site-packages/httpcore/_async/connection.py", line 124, in _connect
    stream = await self._network_backend.connect_tcp(**kwargs)
             ^^^^^^^^^^^^^^^^^^^^^^^^^^^^^^^^^^^^^^^^^^^^^^^^^
  File "/Library/Frameworks/Python.framework/Versions/3.13/lib/python3.13/site-packages/httpcore/_backends/auto.py", line 31, in connect_tcp
    return await self._backend.connect_tcp(
           ^^^^^^^^^^^^^^^^^^^^^^^^^^^^^^^^
    ...<5 lines>...
    )
    ^
  File "/Library/Frameworks/Python.framework/Versions/3.13/lib/python3.13/site-packages/httpcore/_backends/anyio.py", line 113, in connect_tcp
    with map_exceptions(exc_map):
         ~~~~~~~~~~~~~~^^^^^^^^^
  File "/Library/Frameworks/Python.framework/Versions/3.13/lib/python3.13/contextlib.py", line 162, in __exit__
    self.gen.throw(value)
    ~~~~~~~~~~~~~~^^^^^^^
  File "/Library/Frameworks/Python.framework/Versions/3.13/lib/python3.13/site-packages/httpcore/_exceptions.py", line 14, in map_exceptions
    raise to_exc(exc) from exc
httpcore.ConnectError: [Errno 8] nodename nor servname provided, or not known

The above exception was the direct cause of the following exception:

Traceback (most recent call last):
  File "/Library/Frameworks/Python.framework/Versions/3.13/lib/python3.13/site-packages/telegram/request/_httpxrequest.py", line 276, in do_request
    res = await self._client.request(
          ^^^^^^^^^^^^^^^^^^^^^^^^^^^
    ...<6 lines>...
    )
    ^
  File "/Library/Frameworks/Python.framework/Versions/3.13/lib/python3.13/site-packages/httpx/_client.py", line 1540, in request
    return await self.send(request, auth=auth, follow_redirects=follow_redirects)
           ^^^^^^^^^^^^^^^^^^^^^^^^^^^^^^^^^^^^^^^^^^^^^^^^^^^^^^^^^^^^^^^^^^^^^^
  File "/Library/Frameworks/Python.framework/Versions/3.13/lib/python3.13/site-packages/httpx/_client.py", line 1629, in send
    response = await self._send_handling_auth(
               ^^^^^^^^^^^^^^^^^^^^^^^^^^^^^^^
    ...<4 lines>...
    )
    ^
  File "/Library/Frameworks/Python.framework/Versions/3.13/lib/python3.13/site-packages/httpx/_client.py", line 1657, in _send_handling_auth
    response = await self._send_handling_redirects(
               ^^^^^^^^^^^^^^^^^^^^^^^^^^^^^^^^^^^^
    ...<3 lines>...
    )
    ^
  File "/Library/Frameworks/Python.framework/Versions/3.13/lib/python3.13/site-packages/httpx/_client.py", line 1694, in _send_handling_redirects
    response = await self._send_single_request(request)
               ^^^^^^^^^^^^^^^^^^^^^^^^^^^^^^^^^^^^^^^^
  File "/Library/Frameworks/Python.framework/Versions/3.13/lib/python3.13/site-packages/httpx/_client.py", line 1730, in _send_single_request
    response = await transport.handle_async_request(request)
               ^^^^^^^^^^^^^^^^^^^^^^^^^^^^^^^^^^^^^^^^^^^^^
  File "/Library/Frameworks/Python.framework/Versions/3.13/lib/python3.13/site-packages/httpx/_transports/default.py", line 393, in handle_async_request
    with map_httpcore_exceptions():
         ~~~~~~~~~~~~~~~~~~~~~~~^^
  File "/Library/Frameworks/Python.framework/Versions/3.13/lib/python3.13/contextlib.py", line 162, in __exit__
    self.gen.throw(value)
    ~~~~~~~~~~~~~~^^^^^^^
  File "/Library/Frameworks/Python.framework/Versions/3.13/lib/python3.13/site-packages/httpx/_transports/default.py", line 118, in map_httpcore_exceptions
    raise mapped_exc(message) from exc
httpx.ConnectError: [Errno 8] nodename nor servname provided, or not known

The above exception was the direct cause of the following exception:

Traceback (most recent call last):
  File "/Library/Frameworks/Python.framework/Versions/3.13/lib/python3.13/site-packages/telegram/ext/_updater.py", line 755, in _network_loop_retry
    if not await do_action():
           ^^^^^^^^^^^^^^^^^
  File "/Library/Frameworks/Python.framework/Versions/3.13/lib/python3.13/site-packages/telegram/ext/_updater.py", line 749, in do_action
    return action_cb_task.result()
           ~~~~~~~~~~~~~~~~~~~~~^^
  File "/Library/Frameworks/Python.framework/Versions/3.13/lib/python3.13/site-packages/telegram/ext/_updater.py", line 389, in polling_action_cb
    raise exc
  File "/Library/Frameworks/Python.framework/Versions/3.13/lib/python3.13/site-packages/telegram/ext/_updater.py", line 378, in polling_action_cb
    updates = await self.bot.get_updates(
              ^^^^^^^^^^^^^^^^^^^^^^^^^^^
    ...<7 lines>...
    )
    ^
  File "/Library/Frameworks/Python.framework/Versions/3.13/lib/python3.13/site-packages/telegram/ext/_extbot.py", line 649, in get_updates
    updates = await super().get_updates(
              ^^^^^^^^^^^^^^^^^^^^^^^^^^
    ...<9 lines>...
    )
    ^
  File "/Library/Frameworks/Python.framework/Versions/3.13/lib/python3.13/site-packages/telegram/_bot.py", line 4364, in get_updates
    await self._post(
    ^^^^^^^^^^^^^^^^^
    ...<7 lines>...
    ),
    ^
  File "/Library/Frameworks/Python.framework/Versions/3.13/lib/python3.13/site-packages/telegram/_bot.py", line 622, in _post
    return await self._do_post(
           ^^^^^^^^^^^^^^^^^^^^
    ...<6 lines>...
    )
    ^
  File "/Library/Frameworks/Python.framework/Versions/3.13/lib/python3.13/site-packages/telegram/ext/_extbot.py", line 355, in _do_post
    return await super()._do_post(
           ^^^^^^^^^^^^^^^^^^^^^^^
    ...<6 lines>...
    )
    ^
  File "/Library/Frameworks/Python.framework/Versions/3.13/lib/python3.13/site-packages/telegram/_bot.py", line 651, in _do_post
    result = await request.post(
             ^^^^^^^^^^^^^^^^^^^
    ...<6 lines>...
    )
    ^
  File "/Library/Frameworks/Python.framework/Versions/3.13/lib/python3.13/site-packages/telegram/request/_baserequest.py", line 200, in post
    result = await self._request_wrapper(
             ^^^^^^^^^^^^^^^^^^^^^^^^^^^^
    ...<7 lines>...
    )
    ^
  File "/Library/Frameworks/Python.framework/Versions/3.13/lib/python3.13/site-packages/telegram/request/_baserequest.py", line 342, in _request_wrapper
    raise exc
  File "/Library/Frameworks/Python.framework/Versions/3.13/lib/python3.13/site-packages/telegram/request/_baserequest.py", line 332, in _request_wrapper
    code, payload = await self.do_request(
                    ^^^^^^^^^^^^^^^^^^^^^^
    ...<7 lines>...
    )
    ^
  File "/Library/Frameworks/Python.framework/Versions/3.13/lib/python3.13/site-packages/telegram/request/_httpxrequest.py", line 300, in do_request
    raise NetworkError(f"httpx.{err.__class__.__name__}: {err}") from err
telegram.error.NetworkError: httpx.ConnectError: [Errno 8] nodename nor servname provided, or not known
2025-04-22 13:35:13,189 - telegram.ext.Updater - ERROR - Error while getting Updates: httpx.ConnectError: [Errno 8] nodename nor servname provided, or not known
2025-04-22 13:35:13,189 - telegram.ext.Updater - ERROR - Error while getting Updates: httpx.ConnectError: [Errno 8] nodename nor servname provided, or not known
2025-04-22 13:35:13,234 - __main__ - ERROR - Update None вызвал ошибку httpx.ConnectError: [Errno 8] nodename nor servname provided, or not known
Traceback (most recent call last):
  File "/Library/Frameworks/Python.framework/Versions/3.13/lib/python3.13/site-packages/httpx/_transports/default.py", line 101, in map_httpcore_exceptions
    yield
  File "/Library/Frameworks/Python.framework/Versions/3.13/lib/python3.13/site-packages/httpx/_transports/default.py", line 394, in handle_async_request
    resp = await self._pool.handle_async_request(req)
           ^^^^^^^^^^^^^^^^^^^^^^^^^^^^^^^^^^^^^^^^^^
  File "/Library/Frameworks/Python.framework/Versions/3.13/lib/python3.13/site-packages/httpcore/_async/connection_pool.py", line 256, in handle_async_request
    raise exc from None
  File "/Library/Frameworks/Python.framework/Versions/3.13/lib/python3.13/site-packages/httpcore/_async/connection_pool.py", line 236, in handle_async_request
    response = await connection.handle_async_request(
               ^^^^^^^^^^^^^^^^^^^^^^^^^^^^^^^^^^^^^^
        pool_request.request
        ^^^^^^^^^^^^^^^^^^^^
    )
    ^
  File "/Library/Frameworks/Python.framework/Versions/3.13/lib/python3.13/site-packages/httpcore/_async/connection.py", line 101, in handle_async_request
    raise exc
  File "/Library/Frameworks/Python.framework/Versions/3.13/lib/python3.13/site-packages/httpcore/_async/connection.py", line 78, in handle_async_request
    stream = await self._connect(request)
             ^^^^^^^^^^^^^^^^^^^^^^^^^^^^
  File "/Library/Frameworks/Python.framework/Versions/3.13/lib/python3.13/site-packages/httpcore/_async/connection.py", line 124, in _connect
    stream = await self._network_backend.connect_tcp(**kwargs)
             ^^^^^^^^^^^^^^^^^^^^^^^^^^^^^^^^^^^^^^^^^^^^^^^^^
  File "/Library/Frameworks/Python.framework/Versions/3.13/lib/python3.13/site-packages/httpcore/_backends/auto.py", line 31, in connect_tcp
    return await self._backend.connect_tcp(
           ^^^^^^^^^^^^^^^^^^^^^^^^^^^^^^^^
    ...<5 lines>...
    )
    ^
  File "/Library/Frameworks/Python.framework/Versions/3.13/lib/python3.13/site-packages/httpcore/_backends/anyio.py", line 113, in connect_tcp
    with map_exceptions(exc_map):
         ~~~~~~~~~~~~~~^^^^^^^^^
  File "/Library/Frameworks/Python.framework/Versions/3.13/lib/python3.13/contextlib.py", line 162, in __exit__
    self.gen.throw(value)
    ~~~~~~~~~~~~~~^^^^^^^
  File "/Library/Frameworks/Python.framework/Versions/3.13/lib/python3.13/site-packages/httpcore/_exceptions.py", line 14, in map_exceptions
    raise to_exc(exc) from exc
httpcore.ConnectError: [Errno 8] nodename nor servname provided, or not known

The above exception was the direct cause of the following exception:

Traceback (most recent call last):
  File "/Library/Frameworks/Python.framework/Versions/3.13/lib/python3.13/site-packages/telegram/request/_httpxrequest.py", line 276, in do_request
    res = await self._client.request(
          ^^^^^^^^^^^^^^^^^^^^^^^^^^^
    ...<6 lines>...
    )
    ^
  File "/Library/Frameworks/Python.framework/Versions/3.13/lib/python3.13/site-packages/httpx/_client.py", line 1540, in request
    return await self.send(request, auth=auth, follow_redirects=follow_redirects)
           ^^^^^^^^^^^^^^^^^^^^^^^^^^^^^^^^^^^^^^^^^^^^^^^^^^^^^^^^^^^^^^^^^^^^^^
  File "/Library/Frameworks/Python.framework/Versions/3.13/lib/python3.13/site-packages/httpx/_client.py", line 1629, in send
    response = await self._send_handling_auth(
               ^^^^^^^^^^^^^^^^^^^^^^^^^^^^^^^
    ...<4 lines>...
    )
    ^
  File "/Library/Frameworks/Python.framework/Versions/3.13/lib/python3.13/site-packages/httpx/_client.py", line 1657, in _send_handling_auth
    response = await self._send_handling_redirects(
               ^^^^^^^^^^^^^^^^^^^^^^^^^^^^^^^^^^^^
    ...<3 lines>...
    )
    ^
  File "/Library/Frameworks/Python.framework/Versions/3.13/lib/python3.13/site-packages/httpx/_client.py", line 1694, in _send_handling_redirects
    response = await self._send_single_request(request)
               ^^^^^^^^^^^^^^^^^^^^^^^^^^^^^^^^^^^^^^^^
  File "/Library/Frameworks/Python.framework/Versions/3.13/lib/python3.13/site-packages/httpx/_client.py", line 1730, in _send_single_request
    response = await transport.handle_async_request(request)
               ^^^^^^^^^^^^^^^^^^^^^^^^^^^^^^^^^^^^^^^^^^^^^
  File "/Library/Frameworks/Python.framework/Versions/3.13/lib/python3.13/site-packages/httpx/_transports/default.py", line 393, in handle_async_request
    with map_httpcore_exceptions():
         ~~~~~~~~~~~~~~~~~~~~~~~^^
  File "/Library/Frameworks/Python.framework/Versions/3.13/lib/python3.13/contextlib.py", line 162, in __exit__
    self.gen.throw(value)
    ~~~~~~~~~~~~~~^^^^^^^
  File "/Library/Frameworks/Python.framework/Versions/3.13/lib/python3.13/site-packages/httpx/_transports/default.py", line 118, in map_httpcore_exceptions
    raise mapped_exc(message) from exc
httpx.ConnectError: [Errno 8] nodename nor servname provided, or not known

The above exception was the direct cause of the following exception:

Traceback (most recent call last):
  File "/Library/Frameworks/Python.framework/Versions/3.13/lib/python3.13/site-packages/telegram/ext/_updater.py", line 755, in _network_loop_retry
    if not await do_action():
           ^^^^^^^^^^^^^^^^^
  File "/Library/Frameworks/Python.framework/Versions/3.13/lib/python3.13/site-packages/telegram/ext/_updater.py", line 749, in do_action
    return action_cb_task.result()
           ~~~~~~~~~~~~~~~~~~~~~^^
  File "/Library/Frameworks/Python.framework/Versions/3.13/lib/python3.13/site-packages/telegram/ext/_updater.py", line 389, in polling_action_cb
    raise exc
  File "/Library/Frameworks/Python.framework/Versions/3.13/lib/python3.13/site-packages/telegram/ext/_updater.py", line 378, in polling_action_cb
    updates = await self.bot.get_updates(
              ^^^^^^^^^^^^^^^^^^^^^^^^^^^
    ...<7 lines>...
    )
    ^
  File "/Library/Frameworks/Python.framework/Versions/3.13/lib/python3.13/site-packages/telegram/ext/_extbot.py", line 649, in get_updates
    updates = await super().get_updates(
              ^^^^^^^^^^^^^^^^^^^^^^^^^^
    ...<9 lines>...
    )
    ^
  File "/Library/Frameworks/Python.framework/Versions/3.13/lib/python3.13/site-packages/telegram/_bot.py", line 4364, in get_updates
    await self._post(
    ^^^^^^^^^^^^^^^^^
    ...<7 lines>...
    ),
    ^
  File "/Library/Frameworks/Python.framework/Versions/3.13/lib/python3.13/site-packages/telegram/_bot.py", line 622, in _post
    return await self._do_post(
           ^^^^^^^^^^^^^^^^^^^^
    ...<6 lines>...
    )
    ^
  File "/Library/Frameworks/Python.framework/Versions/3.13/lib/python3.13/site-packages/telegram/ext/_extbot.py", line 355, in _do_post
    return await super()._do_post(
           ^^^^^^^^^^^^^^^^^^^^^^^
    ...<6 lines>...
    )
    ^
  File "/Library/Frameworks/Python.framework/Versions/3.13/lib/python3.13/site-packages/telegram/_bot.py", line 651, in _do_post
    result = await request.post(
             ^^^^^^^^^^^^^^^^^^^
    ...<6 lines>...
    )
    ^
  File "/Library/Frameworks/Python.framework/Versions/3.13/lib/python3.13/site-packages/telegram/request/_baserequest.py", line 200, in post
    result = await self._request_wrapper(
             ^^^^^^^^^^^^^^^^^^^^^^^^^^^^
    ...<7 lines>...
    )
    ^
  File "/Library/Frameworks/Python.framework/Versions/3.13/lib/python3.13/site-packages/telegram/request/_baserequest.py", line 342, in _request_wrapper
    raise exc
  File "/Library/Frameworks/Python.framework/Versions/3.13/lib/python3.13/site-packages/telegram/request/_baserequest.py", line 332, in _request_wrapper
    code, payload = await self.do_request(
                    ^^^^^^^^^^^^^^^^^^^^^^
    ...<7 lines>...
    )
    ^
  File "/Library/Frameworks/Python.framework/Versions/3.13/lib/python3.13/site-packages/telegram/request/_httpxrequest.py", line 300, in do_request
    raise NetworkError(f"httpx.{err.__class__.__name__}: {err}") from err
telegram.error.NetworkError: httpx.ConnectError: [Errno 8] nodename nor servname provided, or not known
2025-04-22 13:35:13,234 - __main__ - ERROR - Update None вызвал ошибку httpx.ConnectError: [Errno 8] nodename nor servname provided, or not known
Traceback (most recent call last):
  File "/Library/Frameworks/Python.framework/Versions/3.13/lib/python3.13/site-packages/httpx/_transports/default.py", line 101, in map_httpcore_exceptions
    yield
  File "/Library/Frameworks/Python.framework/Versions/3.13/lib/python3.13/site-packages/httpx/_transports/default.py", line 394, in handle_async_request
    resp = await self._pool.handle_async_request(req)
           ^^^^^^^^^^^^^^^^^^^^^^^^^^^^^^^^^^^^^^^^^^
  File "/Library/Frameworks/Python.framework/Versions/3.13/lib/python3.13/site-packages/httpcore/_async/connection_pool.py", line 256, in handle_async_request
    raise exc from None
  File "/Library/Frameworks/Python.framework/Versions/3.13/lib/python3.13/site-packages/httpcore/_async/connection_pool.py", line 236, in handle_async_request
    response = await connection.handle_async_request(
               ^^^^^^^^^^^^^^^^^^^^^^^^^^^^^^^^^^^^^^
        pool_request.request
        ^^^^^^^^^^^^^^^^^^^^
    )
    ^
  File "/Library/Frameworks/Python.framework/Versions/3.13/lib/python3.13/site-packages/httpcore/_async/connection.py", line 101, in handle_async_request
    raise exc
  File "/Library/Frameworks/Python.framework/Versions/3.13/lib/python3.13/site-packages/httpcore/_async/connection.py", line 78, in handle_async_request
    stream = await self._connect(request)
             ^^^^^^^^^^^^^^^^^^^^^^^^^^^^
  File "/Library/Frameworks/Python.framework/Versions/3.13/lib/python3.13/site-packages/httpcore/_async/connection.py", line 124, in _connect
    stream = await self._network_backend.connect_tcp(**kwargs)
             ^^^^^^^^^^^^^^^^^^^^^^^^^^^^^^^^^^^^^^^^^^^^^^^^^
  File "/Library/Frameworks/Python.framework/Versions/3.13/lib/python3.13/site-packages/httpcore/_backends/auto.py", line 31, in connect_tcp
    return await self._backend.connect_tcp(
           ^^^^^^^^^^^^^^^^^^^^^^^^^^^^^^^^
    ...<5 lines>...
    )
    ^
  File "/Library/Frameworks/Python.framework/Versions/3.13/lib/python3.13/site-packages/httpcore/_backends/anyio.py", line 113, in connect_tcp
    with map_exceptions(exc_map):
         ~~~~~~~~~~~~~~^^^^^^^^^
  File "/Library/Frameworks/Python.framework/Versions/3.13/lib/python3.13/contextlib.py", line 162, in __exit__
    self.gen.throw(value)
    ~~~~~~~~~~~~~~^^^^^^^
  File "/Library/Frameworks/Python.framework/Versions/3.13/lib/python3.13/site-packages/httpcore/_exceptions.py", line 14, in map_exceptions
    raise to_exc(exc) from exc
httpcore.ConnectError: [Errno 8] nodename nor servname provided, or not known

The above exception was the direct cause of the following exception:

Traceback (most recent call last):
  File "/Library/Frameworks/Python.framework/Versions/3.13/lib/python3.13/site-packages/telegram/request/_httpxrequest.py", line 276, in do_request
    res = await self._client.request(
          ^^^^^^^^^^^^^^^^^^^^^^^^^^^
    ...<6 lines>...
    )
    ^
  File "/Library/Frameworks/Python.framework/Versions/3.13/lib/python3.13/site-packages/httpx/_client.py", line 1540, in request
    return await self.send(request, auth=auth, follow_redirects=follow_redirects)
           ^^^^^^^^^^^^^^^^^^^^^^^^^^^^^^^^^^^^^^^^^^^^^^^^^^^^^^^^^^^^^^^^^^^^^^
  File "/Library/Frameworks/Python.framework/Versions/3.13/lib/python3.13/site-packages/httpx/_client.py", line 1629, in send
    response = await self._send_handling_auth(
               ^^^^^^^^^^^^^^^^^^^^^^^^^^^^^^^
    ...<4 lines>...
    )
    ^
  File "/Library/Frameworks/Python.framework/Versions/3.13/lib/python3.13/site-packages/httpx/_client.py", line 1657, in _send_handling_auth
    response = await self._send_handling_redirects(
               ^^^^^^^^^^^^^^^^^^^^^^^^^^^^^^^^^^^^
    ...<3 lines>...
    )
    ^
  File "/Library/Frameworks/Python.framework/Versions/3.13/lib/python3.13/site-packages/httpx/_client.py", line 1694, in _send_handling_redirects
    response = await self._send_single_request(request)
               ^^^^^^^^^^^^^^^^^^^^^^^^^^^^^^^^^^^^^^^^
  File "/Library/Frameworks/Python.framework/Versions/3.13/lib/python3.13/site-packages/httpx/_client.py", line 1730, in _send_single_request
    response = await transport.handle_async_request(request)
               ^^^^^^^^^^^^^^^^^^^^^^^^^^^^^^^^^^^^^^^^^^^^^
  File "/Library/Frameworks/Python.framework/Versions/3.13/lib/python3.13/site-packages/httpx/_transports/default.py", line 393, in handle_async_request
    with map_httpcore_exceptions():
         ~~~~~~~~~~~~~~~~~~~~~~~^^
  File "/Library/Frameworks/Python.framework/Versions/3.13/lib/python3.13/contextlib.py", line 162, in __exit__
    self.gen.throw(value)
    ~~~~~~~~~~~~~~^^^^^^^
  File "/Library/Frameworks/Python.framework/Versions/3.13/lib/python3.13/site-packages/httpx/_transports/default.py", line 118, in map_httpcore_exceptions
    raise mapped_exc(message) from exc
httpx.ConnectError: [Errno 8] nodename nor servname provided, or not known

The above exception was the direct cause of the following exception:

Traceback (most recent call last):
  File "/Library/Frameworks/Python.framework/Versions/3.13/lib/python3.13/site-packages/telegram/ext/_updater.py", line 755, in _network_loop_retry
    if not await do_action():
           ^^^^^^^^^^^^^^^^^
  File "/Library/Frameworks/Python.framework/Versions/3.13/lib/python3.13/site-packages/telegram/ext/_updater.py", line 749, in do_action
    return action_cb_task.result()
           ~~~~~~~~~~~~~~~~~~~~~^^
  File "/Library/Frameworks/Python.framework/Versions/3.13/lib/python3.13/site-packages/telegram/ext/_updater.py", line 389, in polling_action_cb
    raise exc
  File "/Library/Frameworks/Python.framework/Versions/3.13/lib/python3.13/site-packages/telegram/ext/_updater.py", line 378, in polling_action_cb
    updates = await self.bot.get_updates(
              ^^^^^^^^^^^^^^^^^^^^^^^^^^^
    ...<7 lines>...
    )
    ^
  File "/Library/Frameworks/Python.framework/Versions/3.13/lib/python3.13/site-packages/telegram/ext/_extbot.py", line 649, in get_updates
    updates = await super().get_updates(
              ^^^^^^^^^^^^^^^^^^^^^^^^^^
    ...<9 lines>...
    )
    ^
  File "/Library/Frameworks/Python.framework/Versions/3.13/lib/python3.13/site-packages/telegram/_bot.py", line 4364, in get_updates
    await self._post(
    ^^^^^^^^^^^^^^^^^
    ...<7 lines>...
    ),
    ^
  File "/Library/Frameworks/Python.framework/Versions/3.13/lib/python3.13/site-packages/telegram/_bot.py", line 622, in _post
    return await self._do_post(
           ^^^^^^^^^^^^^^^^^^^^
    ...<6 lines>...
    )
    ^
  File "/Library/Frameworks/Python.framework/Versions/3.13/lib/python3.13/site-packages/telegram/ext/_extbot.py", line 355, in _do_post
    return await super()._do_post(
           ^^^^^^^^^^^^^^^^^^^^^^^
    ...<6 lines>...
    )
    ^
  File "/Library/Frameworks/Python.framework/Versions/3.13/lib/python3.13/site-packages/telegram/_bot.py", line 651, in _do_post
    result = await request.post(
             ^^^^^^^^^^^^^^^^^^^
    ...<6 lines>...
    )
    ^
  File "/Library/Frameworks/Python.framework/Versions/3.13/lib/python3.13/site-packages/telegram/request/_baserequest.py", line 200, in post
    result = await self._request_wrapper(
             ^^^^^^^^^^^^^^^^^^^^^^^^^^^^
    ...<7 lines>...
    )
    ^
  File "/Library/Frameworks/Python.framework/Versions/3.13/lib/python3.13/site-packages/telegram/request/_baserequest.py", line 342, in _request_wrapper
    raise exc
  File "/Library/Frameworks/Python.framework/Versions/3.13/lib/python3.13/site-packages/telegram/request/_baserequest.py", line 332, in _request_wrapper
    code, payload = await self.do_request(
                    ^^^^^^^^^^^^^^^^^^^^^^
    ...<7 lines>...
    )
    ^
  File "/Library/Frameworks/Python.framework/Versions/3.13/lib/python3.13/site-packages/telegram/request/_httpxrequest.py", line 300, in do_request
    raise NetworkError(f"httpx.{err.__class__.__name__}: {err}") from err
telegram.error.NetworkError: httpx.ConnectError: [Errno 8] nodename nor servname provided, or not known
2025-04-22 22:37:09,045 - handlers.manual - ERROR - Неизвестная функция расчета 'calculate_concrete_wall_cost', chat_id=539641125
2025-04-22 22:37:09,045 - handlers.manual - ERROR - Ошибка при расчете 'Бетонная стена': Ошибка в настройке расчета, chat_id=539641125
2025-04-22 22:37:23,617 - handlers.manual - ERROR - Неизвестная функция расчета 'calculate_concrete_wall_cost', chat_id=539641125
2025-04-22 22:37:23,618 - handlers.manual - ERROR - Ошибка при расчете 'Бетонная стена': Ошибка в настройке расчета, chat_id=539641125
2025-04-22 22:39:17,411 - handlers.manual - ERROR - Неизвестная функция расчета 'calculate_concrete_wall_cost', chat_id=539641125
2025-04-22 22:39:17,412 - handlers.manual - ERROR - Ошибка при расчете 'Бетонная стена': Ошибка в настройке расчета, chat_id=539641125
